# Errors and Exceptions

발생할 수 있는 오류와 예외처리를 확인해봅시다.



## 문법 에러 (Syntax Error)

가장 많이 만날 수 있는 에러로 발생한 `파일 이름`과 `줄번호`, `^` 문자 을 통해 파이썬이 읽어 들일 때(parser)의 문제 발생 위치를 표현합니다.

`parser` 는 문제가 되는 줄을 다시 보여주고 줄에서 에러가 감지된 가장 앞의 위치를 가리키는 작은 '화살표(`^`)'를 표시합니다.



## Static Semantic 에러

구문적으로 오류가 없으며 (Syntatically valid) 의미를 내포하려 하지만 의미상 오류가 존재

ex) 3+'hi' 숫자, 연산자, 문자의 조합으로 옳은 조합이나 의미가 없는 구문

마치 영어에서 I are hungry 즉 문법은 맞지만 am이 아닌 are 들어감으로써 오류가 있는 상황



## Semantic 에러

의미를 내포하는 가장 상위 단위. Syntatically valid 하고 Static semantic error도 없는 상태이지만, 의미가 의도한 의미와 다를 가능성이 존재한다.



Syntax Error = > handling이 필요한 부분

Static Semantic 에러 , Semantic 에러 => debugging가 필요한 부분



### Syntax Error

```python
# if문을 통해 발생시켜보기
n = 0
if n == 0
    print('zero')
```

```
  File "<ipython-input-1-42d0c990ae46>", line 2
    if n == 0
             ^
SyntaxError: invalid syntax
```

​         

```python
# print문을 통해 다른 오류를 발생시켜봅시다.
# EOL 오류(따옴표 오류) 를 봅시다.

print('#{} {}'.format()
```

```
  File "<ipython-input-2-dc224c76e6d3>", line 1
    print('#{} {}'.format()
                           ^
SyntaxError: unexpected EOF while parsing
```



```python
# 정확한 위치를 지정하지 않을 수도 있으므로 앞뒤로 모두 확인을 해봐야합니다.
if Ture print('참')
```

```
  File "<ipython-input-4-0145c639af0d>", line 1
    if Ture print('참')
                ^
SyntaxError: invalid syntax
```

```python
# True 뒤에 ':'이 빠져있다. => 정확한 위치를 지정하지 않을 수 있다.
if Ture: print('참')
```





## 예외 (Exceptions)

* 문법이나 표현식이 바르게 되어있지만, 실행시 발생하는 에러다.
* 아래 제시된 모든 에러는 Exception을 상속받아 이뤄진다.



```python
# ZeroDivisionError를 확인해봅시다.
# 0으로 나눌수는 없습니다.
10*(1/0)
```

```
---------------------------------------------------------------------------
ZeroDivisionError                         Traceback (most recent call last)
<ipython-input-5-07a5659b36d6> in <module>
      1 # 0으로 나눌수는 없습니다.
----> 2 10*(1/0)

ZeroDivisionError: division by zero
```



```python
# NameError를 확인해봅시다. 
# 지역 혹은 전역 이름 공간내에서 유효하지 않는 이름
# 즉 정의되지 않은 변수를 호출 하였을 경우

print(name)
```

```
---------------------------------------------------------------------------
NameError                                 Traceback (most recent call last)
<ipython-input-6-27263062b109> in <module>
      2 # 즉 정의되지 않은 변수를 호출 하였을 경우
      3 
----> 4 print(name)

NameError: name 'name' is not defined
```



```python
# TypeError를 확인해봅시다.
# 자료형에 대한 타입 자체가 잘못 되었을 경우
print(1 + '1')
```

```
---------------------------------------------------------------------------
TypeError                                 Traceback (most recent call last)
<ipython-input-7-a8978fdced50> in <module>
      1 # TypeError를 확인해봅시다.
----> 2 1 + '1'

TypeError: unsupported operand type(s) for +: 'int' and 'str'
```



```python
# 함수 호출과정에서 TypeError도 발생하게 됩니다. 확인해봅시다.
round('3.5')
```

```
---------------------------------------------------------------------------
TypeError                                 Traceback (most recent call last)
<ipython-input-10-ebbc9f47e959> in <module>
----> 1 round('3.5')

TypeError: type str doesn't define __round__ method
```

```python
import random
random.sample([1,2,3])
```

```
---------------------------------------------------------------------------
TypeError                                 Traceback (most recent call last)
<ipython-input-12-336aecb5aa2f> in <module>
      1 import random
----> 2 random.sample([1,2,3])

TypeError: sample() missing 1 required positional argument: 'k'
```



```python
import random
random.choice([1,2,3],2)
```

```
---------------------------------------------------------------------------
TypeError                                 Traceback (most recent call last)
<ipython-input-13-37e0daccc1e2> in <module>
----> 1 random.choice([1,2,3],2)

TypeError: choice() takes 2 positional arguments but 3 were given
```



```python
# ValueError를 확인해봅시다.
# 자료형에 대한 타입은 올바르나 값이 적절하지 않는 경우
int('3.5')
```

```
---------------------------------------------------------------------------
ValueError                                Traceback (most recent call last)
<ipython-input-14-8ea914687a01> in <module>
      1 # 자료형에 대한 타입은 올바르나 값이 적절하지 않는 경우
----> 2 int('3.5')

ValueError: invalid literal for int() with base 10: '3.5'
```

```python
# ValueError를 확인해봅시다.
# 값이 적절하지 않은 경우(값이 없는데 찾으려고함)

numbers = [1,2,3]
numbers.index(4)
```

```
---------------------------------------------------------------------------
ValueError                                Traceback (most recent call last)
<ipython-input-16-702875ee7a6b> in <module>
      1 # 값이 적절하지 않은 경우(값이 없는데 찾으려고함)
      2 numbers = [1,2,3]
----> 3 numbers.index(4)

ValueError: 4 is not in list
```





```python
# IndexError를 확인해봅시다.

numbers = [1,2,3]
numbers[3]
```

```
---------------------------------------------------------------------------
IndexError                                Traceback (most recent call last)
<ipython-input-17-5b3e1189e579> in <module>
      1 numbers = [1,2,3]
----> 2 numbers[3]

IndexError: list index out of range
```



```python
# KeyError를 확인해봅시다. 
# 딕셔너리에서 Key가 없는 경우 발생합니다.

songs = {'damoim' : 'imma do', 'lauv' : 'paris in the rain'}
songs['changmo']
```

```
---------------------------------------------------------------------------
KeyError                                  Traceback (most recent call last)
<ipython-input-18-a1331a96562f> in <module>
      1 # 딕셔너리에서 Key가 없는 경우 발생합니다.
      2 songs = {'damoim' : 'imma do', 'lauv' : 'paris in the rain'}
----> 3 songs['changmo']

KeyError: 'changmo'
```



```python
# 모듈을 찾을 수 없는 경우 
from collections import reque
```

```
---------------------------------------------------------------------------
ImportError                               Traceback (most recent call last)
<ipython-input-19-2afa5c1afc6e> in <module>
      1 # 모듈을 찾을 수 없는 경우
----> 2 from collections import reque

ImportError: cannot import name 'reque' from 'collections' (c:\users\multicampus\appdata\local\programs\python\python37\lib\collections\__init__.py)
```

```python
# KeyboardInterrupt를 확인해봅시다.
# 주피터 노트북에서는 정지 버튼이지만, 실제로 우리가 돌릴 때는 ctrl+c를 통해 종료하였을 때 발생한다.
while True:
    continue
```

```
---------------------------------------------------------------------------
KeyboardInterrupt                         Traceback (most recent call last)
<ipython-input-21-89cc33ee39df> in <module>
      1 # 주피터 노트북에서는 정지 버튼이지만, 실제로 우리가 돌릴 때는 ctrl+c를 통해 종료하였을 때 발생한다.
      2 while True:
----> 3     continue

KeyboardInterrupt: 
```



   

# 예외 처리 

## 기본  - `try` `except`
`try` 구문을 이용하여 예외 처리를 할 수 있습니다.

---

**활용법**

```python
try:
    codeblock1
except 예외:
    codeblock2
```

* `try`절이 실행된다. 

* 예외가 발생되지 않으면, `except`없이 실행이 종료 된다.

* 예외가 중간에 발생하면, **남은 부분을 수행하지 않고**, `except`가 실행된다.



```python
# 사용자로부터 값을 받아 정수로 변환하여 출력해봅시다.
number = input('숫자 값을 입력하시오 : ')
print(int(number)*2)
```

```
열
```

```
---------------------------------------------------------------------------
ValueError                                Traceback (most recent call last)
<ipython-input-22-c9fd87211793> in <module>
      1 number = input('숫자 값을 입력하시오 : ')
----> 2 print(int(number)*2)

ValueError: invalid literal for int() with base 10: '열'
```

```python
# 사용자가 문자열을 넣어 해당 오류(ValueError)가 발생하면, 숫자를 입력하라고 출력해봅시다.

try:
    # 사용자가 어떤 값을 입력할지 모름(예측할 수 없는 입력값)
    number = input('숫자 값을 입력하시오 : ')
    print(int(number)*2)
except ValueError:
    print('숫자 입력하시오')
```

```
숫자 값을 입력하시오 : 열
숫자 입력하시오
```



## 복수의 예외 처리

하나 이상의 예외를 모두 처리할 수 있습니다. 

괄호가 있는 튜플로 여러 개의 예외를 지정할 수 있습니다.

---

**활용법**

```python
try:
    codeblock1
except (예외1, 예외2):
    codeblock2


try:
    codeblock1
except 예외1:
    codeblock2
except 예외2:
    codeblock3
```



```python
# 100을 사용자가 입력한 값으로 나눈 후 출력하는 코드를 작성해봅시다.

n = int(input('100으로 나눌 값을 입력하세요: '))
print(100/n)
```

```
100으로 나눌 값을 입력하세요: 0
```

```
---------------------------------------------------------------------------
ZeroDivisionError                         Traceback (most recent call last)
<ipython-input-26-4e7b89fced58> in <module>
      2 
      3 n = int(input('100으로 나눌 값을 입력하세요: '))
----> 4 print(100/n)

ZeroDivisionError: division by zero
```

```
100으로 나눌 값을 입력하세요: 열
```

```
---------------------------------------------------------------------------
ValueError                                Traceback (most recent call last)
<ipython-input-27-4e7b89fced58> in <module>
      1 # 100을 사용자가 입력한 값으로 나눈 후 출력하는 코드를 작성해봅시다.
      2 
----> 3 n = int(input('100으로 나눌 값을 입력하세요: '))
      4 print(100/n)

ValueError: invalid literal for int() with base 10: '열'
```

```python
# 문자열일때와 0일때 모두 처리를 해봅시다.

try:
    n = int(input('100을 나눌 값을 입력하세요: '))
    print(100/n)
except (ValueError, ZeroDivisionError):
    print('입력을 잘못하셨습니다.')
```

```
100을 나눌 값을 입력하세요: 열
입력을 잘못하셨습니다.
```

​          

```python
# 각각 다른 오류를 출력할 수 있습니다.

try:
    n = int(input('100을 나눌 값을 입력하세요: '))
    print(100/n)
except ValueError:
    print('글자로 입력하셨습니다.')
#except ZeroDivisionError:
#    print('0으로 나눌 수 없습니다.')

# Error가 순차적으로 수행됨. 가장 작은 범주부터 시작해야 함
except:
    print('알 수 없는 오류가 발생했습니다.')
```

```
100을 나눌 값을 입력하세요: 0
알 수 없는 오류가 발생했습니다.
```

```python
# 각각 다른 오류를 출력할 수 있습니다.

try:
    n = int(input('100을 나눌 값을 입력하세요: '))
    print(100/n)
except ValueError:
    print(f'글자로 입력하셨습니다.{ValueError}')
# except ZeroDivisionError:
#     print('0으로 나눌 수 없습니다.')
except:
    print('알 수 없는 오류가 발생했습니다.')
```

```
100을 나눌 값을 입력하세요: 열
글자로 입력하셨습니다.<class 'ValueError'>
```





## 에러 문구 처리

에러 문구를 함께 넘겨줄 수 있습니다.

---

**활용법**

```python
try:
    codeblock1
except 예외 as err:
    codeblock2
```



```python
# 에러 메세지를 넘겨줄 수도 있습니다.
try:
    numbers = [1,2,3]
    print(numbers[4])
except IndexError as err:
    print(f'{err}, 오류가 발생했습니다.')
```

```
list index out of range 오류가 발생했습니다.
```





## `else`

* **에러가 발생하지 않는 경우** 수행되는 문장은 `else`를 이용한다.
* **모든 except 절 뒤**에와야 한다.
* try 절이 예외를 일으키지 않을 때 실행되어야만 하는 코드에 적절하다.

---

**활용법**

```python
try:
    codeblock1
except 예외:
    codeblock2
else:
    codeblock3
```

```python
# else를 사용해봅시다.

try:
    numbers = [1,2,3]
    number = numbers[2]
except IndexError as err:
    print(f'{err} 발생!')
else:
    print(number * 100)
```

```
300
```





## `finally` 

* 반드시 수행해야하는 문장은 `finally`를 활용한다.
* 즉, **모든 상황에 실행되어야만 하는 코드**를 정의하는데 활용한다.
* 예외의 발생 여부과 관계없이 **try 문을 떠날 때** 항상 실행한다.

---

**활용법**

```python
try:
    codeblock1
except 예외:
    codeblock2
finally:
    codeblock3
```

   

```python
# finally를 사용해봅시다.

try:
    languages = {'python' : 'good', 'java' : 'good'}
    languages['c++']
except KeyError as err:
    # KeyError에서는 에러에 대해 없는 key를 설명한다.
    print(f'{err}는 딕셔너리에 없는 키입니다.')
finally:
    print('모든 동작이 수행되었습니다.')
```

```
'c++'는 딕셔너리에 없는 키입니다.
모든 동작이 수행되었습니다.
```





# 예외 발생시키기

`raise`를 통해 예외를 강제로 발생시킬 수 있습니다.

강제로 RuntimeError을 발생시켰을 때



```python
# raise를 사용해봅시다.

raise
```

```
---------------------------------------------------------------------------
RuntimeError                              Traceback (most recent call last)
<ipython-input-45-9c9a2cba73bf> in <module>
----> 1 raise

RuntimeError: No active exception to reraise
```

```python
raise ValueError('5개 이상 데이터는 조회가 불가합니다.')
```

```
---------------------------------------------------------------------------
ValueError                                Traceback (most recent call last)
<ipython-input-47-de6f97759e5f> in <module>
----> 1 raise ValueError('5개 이상 데이터는 조회가 불가합니다.')

ValueError: 5개 이상 데이터는 조회가 불가합니다.
```







## 실습 문제 1

>양의 정수 두개를 받아 몫을 출력하는 함수 `def my_div(num1, num2)`를 작성하세요.

---

- num2 가 0 이여서 발생하는 오류인 경우 **에러메시지**를 출력합니다.
    - *예) division by zero 오류가 발생하였습니다.*


- 인자가 string 이여서 발생하는 경우는 **ValueError와 함께 '숫자를 넣어주세요'를 출력**합니다.
    - (실제로 이 경우에 발생하는 것은 `TypeError`입니다.)


- 정상적인 경우에는 결과를 return합니다.



```python
def my_div(num1, num2):
    try:
        result = num // num2
    except ZeroDivisionError as err:
        print(f'{err} 오류가 발생하였습니다.')
    except:
        raise ValueError('숫자를 넣어주세요')
    else:
        return result
```

```pyhon
# 해당 코드를 통해 올바른 결과가 나오는지 확인하세요.
my_div(1, 0)
my_div('1', '5')
```

```
integer division or modulo by zero 오류가 발생하였습니다.
---------------------------------------------------------------------------
TypeError                                 Traceback (most recent call last)
<ipython-input-57-05c30ee77f63> in my_div(num1, num2)
      2     try:
----> 3         result = num1 // num2
      4     except ZeroDivisionError as err:

TypeError: unsupported operand type(s) for //: 'str' and 'str'

During handling of the above exception, another exception occurred:

ValueError                                Traceback (most recent call last)
<ipython-input-59-f772f9f9712c> in <module>
      1 # 해당 코드를 통해 올바른 결과가 나오는지 확인하세요.
      2 my_div(1, 0)
----> 3 my_div('1', '5')

<ipython-input-57-05c30ee77f63> in my_div(num1, num2)
      5         print(f'{err} 오류가 발생하였습니다.')
      6     except:
----> 7         raise ValueError('숫자를 넣어주세요')
      8     else:
      9         return result

ValueError: 숫자를 넣어주세요
```





# `assert`

`assert` 문은 예외를 발생시키는 다른 방법입니다. 

보통 **상태를 검증하는데 사용**되며 무조건 `AssertionError`가 발생합니다.

테스트 코드를 짜는 기초적인 작업.

---

**활용법**

```python
assert Boolean expression, error message

# 참일 경우에는 통과하고 아닐 경우에는 뒤의 error message를 출력한다.
assert type(1) == int, '문자열을 입력하였습니다.'
```

---

위의 검증식이 거짓일 경우를 발생합니다.

`raise`는 항상 예외를 발생시키고, 지정한 예외가 발생한다는 점에서 다릅니다.

```python
assert False, '이건 거짓입니다.'
```

```
---------------------------------------------------------------------------
AssertionError                            Traceback (most recent call last)
<ipython-input-61-df94b82747ef> in <module>
----> 1 assert False, '이건 거짓입니다.'

AssertionError: 이건 거짓입니다.
```

```python
assert my_div(4,2) == 3, '테스트를 통과하지 못하였습니다.'
```

```
---------------------------------------------------------------------------
AssertionError                            Traceback (most recent call last)
<ipython-input-64-bcd31eb6525e> in <module>
----> 1 assert my_div(4,2) == 3, '테스트를 통과하지 못하였습니다.'

AssertionError: 테스트를 통과하지 못하였습니다.
```

https://gmlwjd9405.github.io/2018/06/03/agile-tdd.html



## 실습 문제 2

> 양의 정수 두개를 받아 몫과 나머지로 출력하는 함수 `def my_div(num1, num2)`를 작성하세요.

- assert를 활용하여, int가 아닌 경우 AssertionError를 발생시켜주세요.





```python
def my_div(num1, num2):
    assert type(num1)==int and type(num2)==int, '문자열을 입력하였습니다.'
    print('hi')
    try:
        result = num1 / num2
    except ZeroDivisionError as err:
        print(f'{err} 오류가 발생하였습니다.')
    else:
        return result
```

```python
# 해당 코드를 통해 올바른 결과가 나오는지 확인하세요.
my_div('1', '2')
```

```
---------------------------------------------------------------------------
AssertionError                            Traceback (most recent call last)
<ipython-input-66-3ee56f4cdb50> in <module>
      1 # 해당 코드를 통해 올바른 결과가 나오는지 확인하세요.
----> 2 my_div('1', '2')

<ipython-input-65-094675ae2aa8> in my_div(num1, num2)
      1 def my_div(num1, num2):
----> 2     assert type(num1)==int and type(num2)==int, '문자열을 입력하였습니다.'
      3     print('hi')
      4     try:
      5         result = num1 / num2

AssertionError: 문자열을 입력하였습니다.
```

